<?xml version="1.0" ?>
<robot name="P-Rob3">
	<link name="base_link">
		<visual>
			<geometry>
				<mesh filename="file:///home/P-Rob3/meshes/visual/base_link.dae"/>
			</geometry>
		</visual>
		<collision>
			<geometry>
				<mesh filename="file:///home/P-Rob3/meshes/collision/base_link.stl"/>
			</geometry>
		</collision>
	</link>
	<link name="cap_screw">
		<visual>
			<origin xyz="0.0962 0.0 -0.113"/>
			<geometry>
				<mesh filename="file:///home/P-Rob3/meshes/visual/cap_screw.dae"/>
			</geometry>
		</visual>
		<collision>
			<origin xyz="0.0962 0.0 -0.113"/>
			<geometry>
				<mesh filename="file:///home/P-Rob3/meshes/collision/cap_screw.stl"/>
			</geometry>
		</collision>
	</link>
	<joint name="joint_cap_screw_base_link" type="fixed">
		<origin xyz="0.0962 0 0.099"/>
		<parent link="base_link"/>
		<child link="cap_screw"/>
	</joint>
	<link name="link_1_2">
		<visual>
			<origin xyz="0.0 0.0 0.0185"/>
			<geometry>
				<mesh filename="file:///home/P-Rob3/meshes/visual/link_1_2.dae"/>
			</geometry>
		</visual>
		<collision>
			<origin xyz="0.0 0.0 0.0185"/>
			<geometry>
				<mesh filename="file:///home/P-Rob3/meshes/collision/link_1_2.stl"/>
			</geometry>
		</collision>
	</link>
	<joint name="1" type="revolute">
		<origin rpy="0.0 -0.0 0.0" xyz="0.0 0.0 0.212"/>
		<parent link="base_link"/>
		<child link="link_1_2"/>
		<axis xyz="0 0 1"/>
		<limit effort="159.6959" lower="-2.95903" upper="2.95903" velocity="1.74533"/>
	</joint>
	<link name="link_2_3">
		<visual>
			<origin xyz="-0.0 0.0 0.145"/>
			<geometry>
				<mesh filename="file:///home/P-Rob3/meshes/visual/link_2_3.dae"/>
			</geometry>
		</visual>
		<collision>
			<origin xyz="-0.0 0.0 0.145"/>
			<geometry>
				<mesh filename="file:///home/P-Rob3/meshes/collision/link_2_3.stl"/>
			</geometry>
		</collision>
	</link>
	<joint name="2" type="revolute">
		<origin xyz="0.0 0.0 0.1505"/>
		<parent link="link_1_2"/>
		<child link="link_2_3"/>
		<axis xyz="0 1 0"/>
		<limit effort="159.6959" lower="-1.91148" upper="1.91148" velocity="1.74533"/>
	</joint>
	<link name="link_3_4">
		<visual>
			<origin xyz="-0.0 0.0 0.1695"/>
			<geometry>
				<mesh filename="file:///home/P-Rob3/meshes/visual/link_3_4.dae"/>
			</geometry>
		</visual>
		<collision>
			<origin xyz="-0.0 0.0 0.1695"/>
			<geometry>
				<mesh filename="file:///home/P-Rob3/meshes/collision/link_3_4.stl"/>
			</geometry>
		</collision>
	</link>
	<joint name="3" type="revolute">
		<origin xyz="-0.0 0.0 0.29"/>
		<parent link="link_2_3"/>
		<child link="link_3_4"/>
		<axis xyz="0 1 0"/>
		<limit effort="80.1455" lower="-1.99927" upper="1.99927" velocity="2.44346"/>
	</joint>
	<link name="link_4_5">
		<visual>
			<origin xyz="0.0 0.0 0.012"/>
			<geometry>
				<mesh filename="file:///home/P-Rob3/meshes/visual/link_4_5.dae"/>
			</geometry>
		</visual>
		<collision>
			<origin xyz="0.0 0.0 0.012"/>
			<geometry>
				<mesh filename="file:///home/P-Rob3/meshes/collision/link_4_5.stl"/>
			</geometry>
		</collision>
	</link>
	<joint name="4" type="revolute">
		<origin rpy="0.0 -0.0 0.0" xyz="-0.0 0.0 0.164"/>
		<parent link="link_3_4"/>
		<child link="link_4_5"/>
		<axis xyz="0 0 1"/>
		<limit effort="30.1005" lower="-2.95153" upper="2.95153" velocity="2.79253"/>
	</joint>
	<link name="link_5_6">
		<visual>
			<origin xyz="-0.0 0.0 0.1345"/>
			<geometry>
				<mesh filename="file:///home/P-Rob3/meshes/visual/link_5_6.dae"/>
			</geometry>
		</visual>
		<collision>
			<origin xyz="-0.0 0.0 0.1345"/>
			<geometry>
				<mesh filename="file:///home/P-Rob3/meshes/collision/link_5_6.stl"/>
			</geometry>
		</collision>
	</link>
	<joint name="5" type="revolute">
		<origin xyz="0.0 0.0 0.1455"/>
		<parent link="link_4_5"/>
		<child link="link_5_6"/>
		<axis xyz="0 1 0"/>
		<limit effort="30.1005" lower="-1.9977" upper="1.9977" velocity="2.79253"/>
	</joint>
	<link name="link_6_top">
		<visual>
			<origin xyz="0.0 0.0 0.02075"/>
			<geometry>
				<mesh filename="file:///home/P-Rob3/meshes/visual/link_6_top.dae"/>
			</geometry>
		</visual>
		<collision>
			<origin xyz="0.0 0.0 0.02075"/>
			<geometry>
				<mesh filename="file:///home/P-Rob3/meshes/collision/link_6_top.stl"/>
			</geometry>
		</collision>
	</link>
	<joint name="6" type="revolute">
		<origin rpy="0.0 -0.0 0.0" xyz="-0.0 0.0 0.129"/>
		<parent link="link_5_6"/>
		<child link="link_6_top"/>
		<axis xyz="0 0 1"/>
		<limit effort="16.4816" lower="-2.95833" upper="2.95833" velocity="2.79253"/>
	</joint>
	<link name="link_base_tcp180">
		<visual>
			<origin xyz="0.0 0.0 0.01975"/>
			<geometry>
				<mesh filename="file:///home/P-Rob3/meshes/visual/link_base_tcp180.dae"/>
			</geometry>
		</visual>
		<collision>
			<origin xyz="0.0 0.0 0.01975"/>
			<geometry>
				<mesh filename="file:///home/P-Rob3/meshes/collision/link_base_tcp180.stl"/>
			</geometry>
		</collision>
	</link>
	<joint name="joint_link_base_tcp180_link_6_top" type="fixed">
		<origin xyz="0 0 0.07775"/>
		<parent link="link_6_top"/>
		<child link="link_base_tcp180"/>
	</joint>
	<link name="end_effector"/>
	<joint name="joint_end_effector_link_base_tcp180" type="fixed">
		<origin xyz="0 0 0.2"/>
		<parent link="link_base_tcp180"/>
		<child link="end_effector"/>
	</joint>
	<link name="right_finger">
		<visual>
			<origin xyz="0.0 0.0 0.0"/>
			<geometry>
				<mesh filename="file:///home/P-Rob3/meshes/visual/right_finger.dae"/>
			</geometry>
		</visual>
		<collision>
			<origin xyz="0.0 0.0 0.0"/>
			<geometry>
				<mesh filename="file:///home/P-Rob3/meshes/collision/right_finger.stl"/>
			</geometry>
		</collision>
	</link>
	<joint name="7" type="revolute">
		<origin rpy="0.3429999999999781 -0.0 0.0" xyz="0.0 0.0 0.07775"/>
		<parent link="link_base_tcp180"/>
		<child link="right_finger"/>
		<axis xyz="-1 0 0"/>
		<limit effort="5.44164" upper="1.0472" velocity="1.0472"/>
	</joint>
	<link name="left_finger">
		<visual>
			<origin xyz="0.0 0.0 0.0"/>
			<geometry>
				<mesh filename="file:///home/P-Rob3/meshes/visual/left_finger.dae"/>
			</geometry>
		</visual>
		<collision>
			<origin xyz="0.0 0.0 0.0"/>
			<geometry>
				<mesh filename="file:///home/P-Rob3/meshes/collision/left_finger.stl"/>
			</geometry>
		</collision>
	</link>
	<joint name="7_left" type="revolute">
		<origin rpy="0.34300087634523274 4.528642003611354e-07 3.1415900389286664" xyz="0.0 0.0 0.07775"/>
		<parent link="link_base_tcp180"/>
		<child link="left_finger"/>
		<axis xyz="1 0 0"/>
		<limit effort="5.44164" upper="1.0472" velocity="1.0472"/>
	</joint>
</robot>